ERROR:TeleBot:Threaded polling exception: A request to the Telegram API was unsuccessful. Error code: 409. Description: Conflict: terminated by other getUpdates request; make sure that only one bot instance is running
ERROR:TeleBot:Exception traceback:
Traceback (most recent call last):
  File "C:\Users\Asus\AppData\Local\Programs\Python\Python310\lib\site-packages\telebot\__init__.py", line 1077, in __threaded_polling
    polling_thread.raise_exceptions()
  File "C:\Users\Asus\AppData\Local\Programs\Python\Python310\lib\site-packages\telebot\util.py", line 116, in raise_exceptions
    raise self.exception_info
  File "C:\Users\Asus\AppData\Local\Programs\Python\Python310\lib\site-packages\telebot\util.py", line 98, in run
    task(*args, **kwargs)
  File "C:\Users\Asus\AppData\Local\Programs\Python\Python310\lib\site-packages\telebot\__init__.py", line 653, in __retrieve_updates
    updates = self.get_updates(offset=(self.last_update_id + 1),
  File "C:\Users\Asus\AppData\Local\Programs\Python\Python310\lib\site-packages\telebot\__init__.py", line 627, in get_updates
    json_updates = apihelper.get_updates(self.token, offset, limit, timeout, allowed_updates, long_polling_timeout)
  File "C:\Users\Asus\AppData\Local\Programs\Python\Python310\lib\site-packages\telebot\apihelper.py", line 334, in get_updates
    return _make_request(token, method_url, params=payload)
  File "C:\Users\Asus\AppData\Local\Programs\Python\Python310\lib\site-packages\telebot\apihelper.py", line 162, in _make_request
    json_result = _check_result(method_name, result)
  File "C:\Users\Asus\AppData\Local\Programs\Python\Python310\lib\site-packages\telebot\apihelper.py", line 189, in _check_result
    raise ApiTelegramException(method_name, result, result_json)
telebot.apihelper.ApiTelegramException: A request to the Telegram API was unsuccessful. Error code: 409. Description: Conflict: terminated by other getUpdates request; make sure that only one bot instance is running

ERROR:TeleBot:Threaded polling exception: A request to the Telegram API was unsuccessful. Error code: 409. Description: Conflict: terminated by other getUpdates request; make sure that only one bot instance is running
ERROR:TeleBot:Exception traceback:
Traceback (most recent call last):
  File "C:\Users\Asus\AppData\Local\Programs\Python\Python310\lib\site-packages\telebot\__init__.py", line 1077, in __threaded_polling
    polling_thread.raise_exceptions()
  File "C:\Users\Asus\AppData\Local\Programs\Python\Python310\lib\site-packages\telebot\util.py", line 116, in raise_exceptions
    raise self.exception_info
  File "C:\Users\Asus\AppData\Local\Programs\Python\Python310\lib\site-packages\telebot\util.py", line 98, in run
    task(*args, **kwargs)
  File "C:\Users\Asus\AppData\Local\Programs\Python\Python310\lib\site-packages\telebot\__init__.py", line 653, in __retrieve_updates
    updates = self.get_updates(offset=(self.last_update_id + 1),
  File "C:\Users\Asus\AppData\Local\Programs\Python\Python310\lib\site-packages\telebot\__init__.py", line 627, in get_updates
    json_updates = apihelper.get_updates(self.token, offset, limit, timeout, allowed_updates, long_polling_timeout)
  File "C:\Users\Asus\AppData\Local\Programs\Python\Python310\lib\site-packages\telebot\apihelper.py", line 334, in get_updates
    return _make_request(token, method_url, params=payload)
  File "C:\Users\Asus\AppData\Local\Programs\Python\Python310\lib\site-packages\telebot\apihelper.py", line 162, in _make_request
    json_result = _check_result(method_name, result)
  File "C:\Users\Asus\AppData\Local\Programs\Python\Python310\lib\site-packages\telebot\apihelper.py", line 189, in _check_result
    raise ApiTelegramException(method_name, result, result_json)
telebot.apihelper.ApiTelegramException: A request to the Telegram API was unsuccessful. Error code: 409. Description: Conflict: terminated by other getUpdates request; make sure that only one bot instance is running

ERROR:TeleBot:Threaded polling exception: A request to the Telegram API was unsuccessful. Error code: 409. Description: Conflict: terminated by other getUpdates request; make sure that only one bot instance is running
ERROR:TeleBot:Exception traceback:
Traceback (most recent call last):
  File "C:\Users\Asus\AppData\Local\Programs\Python\Python310\lib\site-packages\telebot\__init__.py", line 1077, in __threaded_polling
    polling_thread.raise_exceptions()
  File "C:\Users\Asus\AppData\Local\Programs\Python\Python310\lib\site-packages\telebot\util.py", line 116, in raise_exceptions
    raise self.exception_info
  File "C:\Users\Asus\AppData\Local\Programs\Python\Python310\lib\site-packages\telebot\util.py", line 98, in run
    task(*args, **kwargs)
  File "C:\Users\Asus\AppData\Local\Programs\Python\Python310\lib\site-packages\telebot\__init__.py", line 653, in __retrieve_updates
    updates = self.get_updates(offset=(self.last_update_id + 1),
  File "C:\Users\Asus\AppData\Local\Programs\Python\Python310\lib\site-packages\telebot\__init__.py", line 627, in get_updates
    json_updates = apihelper.get_updates(self.token, offset, limit, timeout, allowed_updates, long_polling_timeout)
  File "C:\Users\Asus\AppData\Local\Programs\Python\Python310\lib\site-packages\telebot\apihelper.py", line 334, in get_updates
    return _make_request(token, method_url, params=payload)
  File "C:\Users\Asus\AppData\Local\Programs\Python\Python310\lib\site-packages\telebot\apihelper.py", line 162, in _make_request
    json_result = _check_result(method_name, result)
  File "C:\Users\Asus\AppData\Local\Programs\Python\Python310\lib\site-packages\telebot\apihelper.py", line 189, in _check_result
    raise ApiTelegramException(method_name, result, result_json)
telebot.apihelper.ApiTelegramException: A request to the Telegram API was unsuccessful. Error code: 409. Description: Conflict: terminated by other getUpdates request; make sure that only one bot instance is running

ERROR:TeleBot:Threaded polling exception: A request to the Telegram API was unsuccessful. Error code: 409. Description: Conflict: terminated by other getUpdates request; make sure that only one bot instance is running
ERROR:TeleBot:Exception traceback:
Traceback (most recent call last):
  File "C:\Users\Asus\AppData\Local\Programs\Python\Python310\lib\site-packages\telebot\__init__.py", line 1077, in __threaded_polling
    polling_thread.raise_exceptions()
  File "C:\Users\Asus\AppData\Local\Programs\Python\Python310\lib\site-packages\telebot\util.py", line 116, in raise_exceptions
    raise self.exception_info
  File "C:\Users\Asus\AppData\Local\Programs\Python\Python310\lib\site-packages\telebot\util.py", line 98, in run
    task(*args, **kwargs)
  File "C:\Users\Asus\AppData\Local\Programs\Python\Python310\lib\site-packages\telebot\__init__.py", line 653, in __retrieve_updates
    updates = self.get_updates(offset=(self.last_update_id + 1),
  File "C:\Users\Asus\AppData\Local\Programs\Python\Python310\lib\site-packages\telebot\__init__.py", line 627, in get_updates
    json_updates = apihelper.get_updates(self.token, offset, limit, timeout, allowed_updates, long_polling_timeout)
  File "C:\Users\Asus\AppData\Local\Programs\Python\Python310\lib\site-packages\telebot\apihelper.py", line 334, in get_updates
    return _make_request(token, method_url, params=payload)
  File "C:\Users\Asus\AppData\Local\Programs\Python\Python310\lib\site-packages\telebot\apihelper.py", line 162, in _make_request
    json_result = _check_result(method_name, result)
  File "C:\Users\Asus\AppData\Local\Programs\Python\Python310\lib\site-packages\telebot\apihelper.py", line 189, in _check_result
    raise ApiTelegramException(method_name, result, result_json)
telebot.apihelper.ApiTelegramException: A request to the Telegram API was unsuccessful. Error code: 409. Description: Conflict: terminated by other getUpdates request; make sure that only one bot instance is running

ERROR:TeleBot:Threaded polling exception: A request to the Telegram API was unsuccessful. Error code: 409. Description: Conflict: terminated by other getUpdates request; make sure that only one bot instance is running
ERROR:TeleBot:Exception traceback:
Traceback (most recent call last):
  File "C:\Users\Asus\AppData\Local\Programs\Python\Python310\lib\site-packages\telebot\__init__.py", line 1077, in __threaded_polling
    polling_thread.raise_exceptions()
  File "C:\Users\Asus\AppData\Local\Programs\Python\Python310\lib\site-packages\telebot\util.py", line 116, in raise_exceptions
    raise self.exception_info
  File "C:\Users\Asus\AppData\Local\Programs\Python\Python310\lib\site-packages\telebot\util.py", line 98, in run
    task(*args, **kwargs)
  File "C:\Users\Asus\AppData\Local\Programs\Python\Python310\lib\site-packages\telebot\__init__.py", line 653, in __retrieve_updates
    updates = self.get_updates(offset=(self.last_update_id + 1),
  File "C:\Users\Asus\AppData\Local\Programs\Python\Python310\lib\site-packages\telebot\__init__.py", line 627, in get_updates
    json_updates = apihelper.get_updates(self.token, offset, limit, timeout, allowed_updates, long_polling_timeout)
  File "C:\Users\Asus\AppData\Local\Programs\Python\Python310\lib\site-packages\telebot\apihelper.py", line 334, in get_updates
    return _make_request(token, method_url, params=payload)
  File "C:\Users\Asus\AppData\Local\Programs\Python\Python310\lib\site-packages\telebot\apihelper.py", line 162, in _make_request
    json_result = _check_result(method_name, result)
  File "C:\Users\Asus\AppData\Local\Programs\Python\Python310\lib\site-packages\telebot\apihelper.py", line 189, in _check_result
    raise ApiTelegramException(method_name, result, result_json)
telebot.apihelper.ApiTelegramException: A request to the Telegram API was unsuccessful. Error code: 409. Description: Conflict: terminated by other getUpdates request; make sure that only one bot instance is running

ERROR:TeleBot:Threaded polling exception: A request to the Telegram API was unsuccessful. Error code: 409. Description: Conflict: terminated by other getUpdates request; make sure that only one bot instance is running
ERROR:TeleBot:Exception traceback:
Traceback (most recent call last):
  File "C:\Users\Asus\AppData\Local\Programs\Python\Python310\lib\site-packages\telebot\__init__.py", line 1077, in __threaded_polling
    polling_thread.raise_exceptions()
  File "C:\Users\Asus\AppData\Local\Programs\Python\Python310\lib\site-packages\telebot\util.py", line 116, in raise_exceptions
    raise self.exception_info
  File "C:\Users\Asus\AppData\Local\Programs\Python\Python310\lib\site-packages\telebot\util.py", line 98, in run
    task(*args, **kwargs)
  File "C:\Users\Asus\AppData\Local\Programs\Python\Python310\lib\site-packages\telebot\__init__.py", line 653, in __retrieve_updates
    updates = self.get_updates(offset=(self.last_update_id + 1),
  File "C:\Users\Asus\AppData\Local\Programs\Python\Python310\lib\site-packages\telebot\__init__.py", line 627, in get_updates
    json_updates = apihelper.get_updates(self.token, offset, limit, timeout, allowed_updates, long_polling_timeout)
  File "C:\Users\Asus\AppData\Local\Programs\Python\Python310\lib\site-packages\telebot\apihelper.py", line 334, in get_updates
    return _make_request(token, method_url, params=payload)
  File "C:\Users\Asus\AppData\Local\Programs\Python\Python310\lib\site-packages\telebot\apihelper.py", line 162, in _make_request
    json_result = _check_result(method_name, result)
  File "C:\Users\Asus\AppData\Local\Programs\Python\Python310\lib\site-packages\telebot\apihelper.py", line 189, in _check_result
    raise ApiTelegramException(method_name, result, result_json)
telebot.apihelper.ApiTelegramException: A request to the Telegram API was unsuccessful. Error code: 409. Description: Conflict: terminated by other getUpdates request; make sure that only one bot instance is running

ERROR:TeleBot:Threaded polling exception: A request to the Telegram API was unsuccessful. Error code: 409. Description: Conflict: terminated by other getUpdates request; make sure that only one bot instance is running
ERROR:TeleBot:Exception traceback:
Traceback (most recent call last):
  File "C:\Users\Asus\AppData\Local\Programs\Python\Python310\lib\site-packages\telebot\__init__.py", line 1077, in __threaded_polling
    polling_thread.raise_exceptions()
  File "C:\Users\Asus\AppData\Local\Programs\Python\Python310\lib\site-packages\telebot\util.py", line 116, in raise_exceptions
    raise self.exception_info
  File "C:\Users\Asus\AppData\Local\Programs\Python\Python310\lib\site-packages\telebot\util.py", line 98, in run
    task(*args, **kwargs)
  File "C:\Users\Asus\AppData\Local\Programs\Python\Python310\lib\site-packages\telebot\__init__.py", line 653, in __retrieve_updates
    updates = self.get_updates(offset=(self.last_update_id + 1),
  File "C:\Users\Asus\AppData\Local\Programs\Python\Python310\lib\site-packages\telebot\__init__.py", line 627, in get_updates
    json_updates = apihelper.get_updates(self.token, offset, limit, timeout, allowed_updates, long_polling_timeout)
  File "C:\Users\Asus\AppData\Local\Programs\Python\Python310\lib\site-packages\telebot\apihelper.py", line 334, in get_updates
    return _make_request(token, method_url, params=payload)
  File "C:\Users\Asus\AppData\Local\Programs\Python\Python310\lib\site-packages\telebot\apihelper.py", line 162, in _make_request
    json_result = _check_result(method_name, result)
  File "C:\Users\Asus\AppData\Local\Programs\Python\Python310\lib\site-packages\telebot\apihelper.py", line 189, in _check_result
    raise ApiTelegramException(method_name, result, result_json)
telebot.apihelper.ApiTelegramException: A request to the Telegram API was unsuccessful. Error code: 409. Description: Conflict: terminated by other getUpdates request; make sure that only one bot instance is running

ERROR:TeleBot:Threaded polling exception: A request to the Telegram API was unsuccessful. Error code: 409. Description: Conflict: terminated by other getUpdates request; make sure that only one bot instance is running
ERROR:TeleBot:Exception traceback:
Traceback (most recent call last):
  File "C:\Users\Asus\AppData\Local\Programs\Python\Python310\lib\site-packages\telebot\__init__.py", line 1077, in __threaded_polling
    polling_thread.raise_exceptions()
  File "C:\Users\Asus\AppData\Local\Programs\Python\Python310\lib\site-packages\telebot\util.py", line 116, in raise_exceptions
    raise self.exception_info
  File "C:\Users\Asus\AppData\Local\Programs\Python\Python310\lib\site-packages\telebot\util.py", line 98, in run
    task(*args, **kwargs)
  File "C:\Users\Asus\AppData\Local\Programs\Python\Python310\lib\site-packages\telebot\__init__.py", line 653, in __retrieve_updates
    updates = self.get_updates(offset=(self.last_update_id + 1),
  File "C:\Users\Asus\AppData\Local\Programs\Python\Python310\lib\site-packages\telebot\__init__.py", line 627, in get_updates
    json_updates = apihelper.get_updates(self.token, offset, limit, timeout, allowed_updates, long_polling_timeout)
  File "C:\Users\Asus\AppData\Local\Programs\Python\Python310\lib\site-packages\telebot\apihelper.py", line 334, in get_updates
    return _make_request(token, method_url, params=payload)
  File "C:\Users\Asus\AppData\Local\Programs\Python\Python310\lib\site-packages\telebot\apihelper.py", line 162, in _make_request
    json_result = _check_result(method_name, result)
  File "C:\Users\Asus\AppData\Local\Programs\Python\Python310\lib\site-packages\telebot\apihelper.py", line 189, in _check_result
    raise ApiTelegramException(method_name, result, result_json)
telebot.apihelper.ApiTelegramException: A request to the Telegram API was unsuccessful. Error code: 409. Description: Conflict: terminated by other getUpdates request; make sure that only one bot instance is running

INFO:root:Bot status: Active
ERROR:TeleBot:Threaded polling exception: A request to the Telegram API was unsuccessful. Error code: 409. Description: Conflict: terminated by other getUpdates request; make sure that only one bot instance is running
ERROR:TeleBot:Exception traceback:
Traceback (most recent call last):
  File "C:\Users\Asus\AppData\Local\Programs\Python\Python310\lib\site-packages\telebot\__init__.py", line 1077, in __threaded_polling
    polling_thread.raise_exceptions()
  File "C:\Users\Asus\AppData\Local\Programs\Python\Python310\lib\site-packages\telebot\util.py", line 116, in raise_exceptions
    raise self.exception_info
  File "C:\Users\Asus\AppData\Local\Programs\Python\Python310\lib\site-packages\telebot\util.py", line 98, in run
    task(*args, **kwargs)
  File "C:\Users\Asus\AppData\Local\Programs\Python\Python310\lib\site-packages\telebot\__init__.py", line 653, in __retrieve_updates
    updates = self.get_updates(offset=(self.last_update_id + 1),
  File "C:\Users\Asus\AppData\Local\Programs\Python\Python310\lib\site-packages\telebot\__init__.py", line 627, in get_updates
    json_updates = apihelper.get_updates(self.token, offset, limit, timeout, allowed_updates, long_polling_timeout)
  File "C:\Users\Asus\AppData\Local\Programs\Python\Python310\lib\site-packages\telebot\apihelper.py", line 334, in get_updates
    return _make_request(token, method_url, params=payload)
  File "C:\Users\Asus\AppData\Local\Programs\Python\Python310\lib\site-packages\telebot\apihelper.py", line 162, in _make_request
    json_result = _check_result(method_name, result)
  File "C:\Users\Asus\AppData\Local\Programs\Python\Python310\lib\site-packages\telebot\apihelper.py", line 189, in _check_result
    raise ApiTelegramException(method_name, result, result_json)
telebot.apihelper.ApiTelegramException: A request to the Telegram API was unsuccessful. Error code: 409. Description: Conflict: terminated by other getUpdates request; make sure that only one bot instance is running

ERROR:TeleBot:Threaded polling exception: A request to the Telegram API was unsuccessful. Error code: 409. Description: Conflict: terminated by other getUpdates request; make sure that only one bot instance is running
ERROR:TeleBot:Exception traceback:
Traceback (most recent call last):
  File "C:\Users\Asus\AppData\Local\Programs\Python\Python310\lib\site-packages\telebot\__init__.py", line 1077, in __threaded_polling
    polling_thread.raise_exceptions()
  File "C:\Users\Asus\AppData\Local\Programs\Python\Python310\lib\site-packages\telebot\util.py", line 116, in raise_exceptions
    raise self.exception_info
  File "C:\Users\Asus\AppData\Local\Programs\Python\Python310\lib\site-packages\telebot\util.py", line 98, in run
    task(*args, **kwargs)
  File "C:\Users\Asus\AppData\Local\Programs\Python\Python310\lib\site-packages\telebot\__init__.py", line 653, in __retrieve_updates
    updates = self.get_updates(offset=(self.last_update_id + 1),
  File "C:\Users\Asus\AppData\Local\Programs\Python\Python310\lib\site-packages\telebot\__init__.py", line 627, in get_updates
    json_updates = apihelper.get_updates(self.token, offset, limit, timeout, allowed_updates, long_polling_timeout)
  File "C:\Users\Asus\AppData\Local\Programs\Python\Python310\lib\site-packages\telebot\apihelper.py", line 334, in get_updates
    return _make_request(token, method_url, params=payload)
  File "C:\Users\Asus\AppData\Local\Programs\Python\Python310\lib\site-packages\telebot\apihelper.py", line 162, in _make_request
    json_result = _check_result(method_name, result)
  File "C:\Users\Asus\AppData\Local\Programs\Python\Python310\lib\site-packages\telebot\apihelper.py", line 189, in _check_result
    raise ApiTelegramException(method_name, result, result_json)
telebot.apihelper.ApiTelegramException: A request to the Telegram API was unsuccessful. Error code: 409. Description: Conflict: terminated by other getUpdates request; make sure that only one bot instance is running

ERROR:TeleBot:Threaded polling exception: A request to the Telegram API was unsuccessful. Error code: 409. Description: Conflict: terminated by other getUpdates request; make sure that only one bot instance is running
ERROR:TeleBot:Exception traceback:
Traceback (most recent call last):
  File "C:\Users\Asus\AppData\Local\Programs\Python\Python310\lib\site-packages\telebot\__init__.py", line 1077, in __threaded_polling
    polling_thread.raise_exceptions()
  File "C:\Users\Asus\AppData\Local\Programs\Python\Python310\lib\site-packages\telebot\util.py", line 116, in raise_exceptions
    raise self.exception_info
  File "C:\Users\Asus\AppData\Local\Programs\Python\Python310\lib\site-packages\telebot\util.py", line 98, in run
    task(*args, **kwargs)
  File "C:\Users\Asus\AppData\Local\Programs\Python\Python310\lib\site-packages\telebot\__init__.py", line 653, in __retrieve_updates
    updates = self.get_updates(offset=(self.last_update_id + 1),
  File "C:\Users\Asus\AppData\Local\Programs\Python\Python310\lib\site-packages\telebot\__init__.py", line 627, in get_updates
    json_updates = apihelper.get_updates(self.token, offset, limit, timeout, allowed_updates, long_polling_timeout)
  File "C:\Users\Asus\AppData\Local\Programs\Python\Python310\lib\site-packages\telebot\apihelper.py", line 334, in get_updates
    return _make_request(token, method_url, params=payload)
  File "C:\Users\Asus\AppData\Local\Programs\Python\Python310\lib\site-packages\telebot\apihelper.py", line 162, in _make_request
    json_result = _check_result(method_name, result)
  File "C:\Users\Asus\AppData\Local\Programs\Python\Python310\lib\site-packages\telebot\apihelper.py", line 189, in _check_result
    raise ApiTelegramException(method_name, result, result_json)
telebot.apihelper.ApiTelegramException: A request to the Telegram API was unsuccessful. Error code: 409. Description: Conflict: terminated by other getUpdates request; make sure that only one bot instance is running

ERROR:TeleBot:Threaded polling exception: A request to the Telegram API was unsuccessful. Error code: 409. Description: Conflict: terminated by other getUpdates request; make sure that only one bot instance is running
ERROR:TeleBot:Exception traceback:
Traceback (most recent call last):
  File "C:\Users\Asus\AppData\Local\Programs\Python\Python310\lib\site-packages\telebot\__init__.py", line 1077, in __threaded_polling
    polling_thread.raise_exceptions()
  File "C:\Users\Asus\AppData\Local\Programs\Python\Python310\lib\site-packages\telebot\util.py", line 116, in raise_exceptions
    raise self.exception_info
  File "C:\Users\Asus\AppData\Local\Programs\Python\Python310\lib\site-packages\telebot\util.py", line 98, in run
    task(*args, **kwargs)
  File "C:\Users\Asus\AppData\Local\Programs\Python\Python310\lib\site-packages\telebot\__init__.py", line 653, in __retrieve_updates
    updates = self.get_updates(offset=(self.last_update_id + 1),
  File "C:\Users\Asus\AppData\Local\Programs\Python\Python310\lib\site-packages\telebot\__init__.py", line 627, in get_updates
    json_updates = apihelper.get_updates(self.token, offset, limit, timeout, allowed_updates, long_polling_timeout)
  File "C:\Users\Asus\AppData\Local\Programs\Python\Python310\lib\site-packages\telebot\apihelper.py", line 334, in get_updates
    return _make_request(token, method_url, params=payload)
  File "C:\Users\Asus\AppData\Local\Programs\Python\Python310\lib\site-packages\telebot\apihelper.py", line 162, in _make_request
    json_result = _check_result(method_name, result)
  File "C:\Users\Asus\AppData\Local\Programs\Python\Python310\lib\site-packages\telebot\apihelper.py", line 189, in _check_result
    raise ApiTelegramException(method_name, result, result_json)
telebot.apihelper.ApiTelegramException: A request to the Telegram API was unsuccessful. Error code: 409. Description: Conflict: terminated by other getUpdates request; make sure that only one bot instance is running

ERROR:TeleBot:Threaded polling exception: A request to the Telegram API was unsuccessful. Error code: 409. Description: Conflict: terminated by other getUpdates request; make sure that only one bot instance is running
ERROR:TeleBot:Exception traceback:
Traceback (most recent call last):
  File "C:\Users\Asus\AppData\Local\Programs\Python\Python310\lib\site-packages\telebot\__init__.py", line 1077, in __threaded_polling
    polling_thread.raise_exceptions()
  File "C:\Users\Asus\AppData\Local\Programs\Python\Python310\lib\site-packages\telebot\util.py", line 116, in raise_exceptions
    raise self.exception_info
  File "C:\Users\Asus\AppData\Local\Programs\Python\Python310\lib\site-packages\telebot\util.py", line 98, in run
    task(*args, **kwargs)
  File "C:\Users\Asus\AppData\Local\Programs\Python\Python310\lib\site-packages\telebot\__init__.py", line 653, in __retrieve_updates
    updates = self.get_updates(offset=(self.last_update_id + 1),
  File "C:\Users\Asus\AppData\Local\Programs\Python\Python310\lib\site-packages\telebot\__init__.py", line 627, in get_updates
    json_updates = apihelper.get_updates(self.token, offset, limit, timeout, allowed_updates, long_polling_timeout)
  File "C:\Users\Asus\AppData\Local\Programs\Python\Python310\lib\site-packages\telebot\apihelper.py", line 334, in get_updates
    return _make_request(token, method_url, params=payload)
  File "C:\Users\Asus\AppData\Local\Programs\Python\Python310\lib\site-packages\telebot\apihelper.py", line 162, in _make_request
    json_result = _check_result(method_name, result)
  File "C:\Users\Asus\AppData\Local\Programs\Python\Python310\lib\site-packages\telebot\apihelper.py", line 189, in _check_result
    raise ApiTelegramException(method_name, result, result_json)
telebot.apihelper.ApiTelegramException: A request to the Telegram API was unsuccessful. Error code: 409. Description: Conflict: terminated by other getUpdates request; make sure that only one bot instance is running

ERROR:TeleBot:Threaded polling exception: A request to the Telegram API was unsuccessful. Error code: 409. Description: Conflict: terminated by other getUpdates request; make sure that only one bot instance is running
ERROR:TeleBot:Exception traceback:
Traceback (most recent call last):
  File "C:\Users\Asus\AppData\Local\Programs\Python\Python310\lib\site-packages\telebot\__init__.py", line 1077, in __threaded_polling
    polling_thread.raise_exceptions()
  File "C:\Users\Asus\AppData\Local\Programs\Python\Python310\lib\site-packages\telebot\util.py", line 116, in raise_exceptions
    raise self.exception_info
  File "C:\Users\Asus\AppData\Local\Programs\Python\Python310\lib\site-packages\telebot\util.py", line 98, in run
    task(*args, **kwargs)
  File "C:\Users\Asus\AppData\Local\Programs\Python\Python310\lib\site-packages\telebot\__init__.py", line 653, in __retrieve_updates
    updates = self.get_updates(offset=(self.last_update_id + 1),
  File "C:\Users\Asus\AppData\Local\Programs\Python\Python310\lib\site-packages\telebot\__init__.py", line 627, in get_updates
    json_updates = apihelper.get_updates(self.token, offset, limit, timeout, allowed_updates, long_polling_timeout)
  File "C:\Users\Asus\AppData\Local\Programs\Python\Python310\lib\site-packages\telebot\apihelper.py", line 334, in get_updates
    return _make_request(token, method_url, params=payload)
  File "C:\Users\Asus\AppData\Local\Programs\Python\Python310\lib\site-packages\telebot\apihelper.py", line 162, in _make_request
    json_result = _check_result(method_name, result)
  File "C:\Users\Asus\AppData\Local\Programs\Python\Python310\lib\site-packages\telebot\apihelper.py", line 189, in _check_result
    raise ApiTelegramException(method_name, result, result_json)
telebot.apihelper.ApiTelegramException: A request to the Telegram API was unsuccessful. Error code: 409. Description: Conflict: terminated by other getUpdates request; make sure that only one bot instance is running

ERROR:TeleBot:Threaded polling exception: A request to the Telegram API was unsuccessful. Error code: 409. Description: Conflict: terminated by other getUpdates request; make sure that only one bot instance is running
ERROR:TeleBot:Exception traceback:
Traceback (most recent call last):
  File "C:\Users\Asus\AppData\Local\Programs\Python\Python310\lib\site-packages\telebot\__init__.py", line 1077, in __threaded_polling
    polling_thread.raise_exceptions()
  File "C:\Users\Asus\AppData\Local\Programs\Python\Python310\lib\site-packages\telebot\util.py", line 116, in raise_exceptions
    raise self.exception_info
  File "C:\Users\Asus\AppData\Local\Programs\Python\Python310\lib\site-packages\telebot\util.py", line 98, in run
    task(*args, **kwargs)
  File "C:\Users\Asus\AppData\Local\Programs\Python\Python310\lib\site-packages\telebot\__init__.py", line 653, in __retrieve_updates
    updates = self.get_updates(offset=(self.last_update_id + 1),
  File "C:\Users\Asus\AppData\Local\Programs\Python\Python310\lib\site-packages\telebot\__init__.py", line 627, in get_updates
    json_updates = apihelper.get_updates(self.token, offset, limit, timeout, allowed_updates, long_polling_timeout)
  File "C:\Users\Asus\AppData\Local\Programs\Python\Python310\lib\site-packages\telebot\apihelper.py", line 334, in get_updates
    return _make_request(token, method_url, params=payload)
  File "C:\Users\Asus\AppData\Local\Programs\Python\Python310\lib\site-packages\telebot\apihelper.py", line 162, in _make_request
    json_result = _check_result(method_name, result)
  File "C:\Users\Asus\AppData\Local\Programs\Python\Python310\lib\site-packages\telebot\apihelper.py", line 189, in _check_result
    raise ApiTelegramException(method_name, result, result_json)
telebot.apihelper.ApiTelegramException: A request to the Telegram API was unsuccessful. Error code: 409. Description: Conflict: terminated by other getUpdates request; make sure that only one bot instance is running

ERROR:TeleBot:Threaded polling exception: A request to the Telegram API was unsuccessful. Error code: 409. Description: Conflict: terminated by other getUpdates request; make sure that only one bot instance is running
ERROR:TeleBot:Exception traceback:
Traceback (most recent call last):
  File "C:\Users\Asus\AppData\Local\Programs\Python\Python310\lib\site-packages\telebot\__init__.py", line 1077, in __threaded_polling
    polling_thread.raise_exceptions()
  File "C:\Users\Asus\AppData\Local\Programs\Python\Python310\lib\site-packages\telebot\util.py", line 116, in raise_exceptions
    raise self.exception_info
  File "C:\Users\Asus\AppData\Local\Programs\Python\Python310\lib\site-packages\telebot\util.py", line 98, in run
    task(*args, **kwargs)
  File "C:\Users\Asus\AppData\Local\Programs\Python\Python310\lib\site-packages\telebot\__init__.py", line 653, in __retrieve_updates
    updates = self.get_updates(offset=(self.last_update_id + 1),
  File "C:\Users\Asus\AppData\Local\Programs\Python\Python310\lib\site-packages\telebot\__init__.py", line 627, in get_updates
    json_updates = apihelper.get_updates(self.token, offset, limit, timeout, allowed_updates, long_polling_timeout)
  File "C:\Users\Asus\AppData\Local\Programs\Python\Python310\lib\site-packages\telebot\apihelper.py", line 334, in get_updates
    return _make_request(token, method_url, params=payload)
  File "C:\Users\Asus\AppData\Local\Programs\Python\Python310\lib\site-packages\telebot\apihelper.py", line 162, in _make_request
    json_result = _check_result(method_name, result)
  File "C:\Users\Asus\AppData\Local\Programs\Python\Python310\lib\site-packages\telebot\apihelper.py", line 189, in _check_result
    raise ApiTelegramException(method_name, result, result_json)
telebot.apihelper.ApiTelegramException: A request to the Telegram API was unsuccessful. Error code: 409. Description: Conflict: terminated by other getUpdates request; make sure that only one bot instance is running

ERROR:TeleBot:Threaded polling exception: A request to the Telegram API was unsuccessful. Error code: 409. Description: Conflict: terminated by other getUpdates request; make sure that only one bot instance is running
ERROR:TeleBot:Exception traceback:
Traceback (most recent call last):
  File "C:\Users\Asus\AppData\Local\Programs\Python\Python310\lib\site-packages\telebot\__init__.py", line 1077, in __threaded_polling
    polling_thread.raise_exceptions()
  File "C:\Users\Asus\AppData\Local\Programs\Python\Python310\lib\site-packages\telebot\util.py", line 116, in raise_exceptions
    raise self.exception_info
  File "C:\Users\Asus\AppData\Local\Programs\Python\Python310\lib\site-packages\telebot\util.py", line 98, in run
    task(*args, **kwargs)
  File "C:\Users\Asus\AppData\Local\Programs\Python\Python310\lib\site-packages\telebot\__init__.py", line 653, in __retrieve_updates
    updates = self.get_updates(offset=(self.last_update_id + 1),
  File "C:\Users\Asus\AppData\Local\Programs\Python\Python310\lib\site-packages\telebot\__init__.py", line 627, in get_updates
    json_updates = apihelper.get_updates(self.token, offset, limit, timeout, allowed_updates, long_polling_timeout)
  File "C:\Users\Asus\AppData\Local\Programs\Python\Python310\lib\site-packages\telebot\apihelper.py", line 334, in get_updates
    return _make_request(token, method_url, params=payload)
  File "C:\Users\Asus\AppData\Local\Programs\Python\Python310\lib\site-packages\telebot\apihelper.py", line 162, in _make_request
    json_result = _check_result(method_name, result)
  File "C:\Users\Asus\AppData\Local\Programs\Python\Python310\lib\site-packages\telebot\apihelper.py", line 189, in _check_result
    raise ApiTelegramException(method_name, result, result_json)
telebot.apihelper.ApiTelegramException: A request to the Telegram API was unsuccessful. Error code: 409. Description: Conflict: terminated by other getUpdates request; make sure that only one bot instance is running

ERROR:TeleBot:Threaded polling exception: A request to the Telegram API was unsuccessful. Error code: 409. Description: Conflict: terminated by other getUpdates request; make sure that only one bot instance is running
ERROR:TeleBot:Exception traceback:
Traceback (most recent call last):
  File "C:\Users\Asus\AppData\Local\Programs\Python\Python310\lib\site-packages\telebot\__init__.py", line 1077, in __threaded_polling
    polling_thread.raise_exceptions()
  File "C:\Users\Asus\AppData\Local\Programs\Python\Python310\lib\site-packages\telebot\util.py", line 116, in raise_exceptions
    raise self.exception_info
  File "C:\Users\Asus\AppData\Local\Programs\Python\Python310\lib\site-packages\telebot\util.py", line 98, in run
    task(*args, **kwargs)
  File "C:\Users\Asus\AppData\Local\Programs\Python\Python310\lib\site-packages\telebot\__init__.py", line 653, in __retrieve_updates
    updates = self.get_updates(offset=(self.last_update_id + 1),
  File "C:\Users\Asus\AppData\Local\Programs\Python\Python310\lib\site-packages\telebot\__init__.py", line 627, in get_updates
    json_updates = apihelper.get_updates(self.token, offset, limit, timeout, allowed_updates, long_polling_timeout)
  File "C:\Users\Asus\AppData\Local\Programs\Python\Python310\lib\site-packages\telebot\apihelper.py", line 334, in get_updates
    return _make_request(token, method_url, params=payload)
  File "C:\Users\Asus\AppData\Local\Programs\Python\Python310\lib\site-packages\telebot\apihelper.py", line 162, in _make_request
    json_result = _check_result(method_name, result)
  File "C:\Users\Asus\AppData\Local\Programs\Python\Python310\lib\site-packages\telebot\apihelper.py", line 189, in _check_result
    raise ApiTelegramException(method_name, result, result_json)
telebot.apihelper.ApiTelegramException: A request to the Telegram API was unsuccessful. Error code: 409. Description: Conflict: terminated by other getUpdates request; make sure that only one bot instance is running

ERROR:TeleBot:Threaded polling exception: A request to the Telegram API was unsuccessful. Error code: 409. Description: Conflict: terminated by other getUpdates request; make sure that only one bot instance is running
ERROR:TeleBot:Exception traceback:
Traceback (most recent call last):
  File "C:\Users\Asus\AppData\Local\Programs\Python\Python310\lib\site-packages\telebot\__init__.py", line 1077, in __threaded_polling
    polling_thread.raise_exceptions()
  File "C:\Users\Asus\AppData\Local\Programs\Python\Python310\lib\site-packages\telebot\util.py", line 116, in raise_exceptions
    raise self.exception_info
  File "C:\Users\Asus\AppData\Local\Programs\Python\Python310\lib\site-packages\telebot\util.py", line 98, in run
    task(*args, **kwargs)
  File "C:\Users\Asus\AppData\Local\Programs\Python\Python310\lib\site-packages\telebot\__init__.py", line 653, in __retrieve_updates
    updates = self.get_updates(offset=(self.last_update_id + 1),
  File "C:\Users\Asus\AppData\Local\Programs\Python\Python310\lib\site-packages\telebot\__init__.py", line 627, in get_updates
    json_updates = apihelper.get_updates(self.token, offset, limit, timeout, allowed_updates, long_polling_timeout)
  File "C:\Users\Asus\AppData\Local\Programs\Python\Python310\lib\site-packages\telebot\apihelper.py", line 334, in get_updates
    return _make_request(token, method_url, params=payload)
  File "C:\Users\Asus\AppData\Local\Programs\Python\Python310\lib\site-packages\telebot\apihelper.py", line 162, in _make_request
    json_result = _check_result(method_name, result)
  File "C:\Users\Asus\AppData\Local\Programs\Python\Python310\lib\site-packages\telebot\apihelper.py", line 189, in _check_result
    raise ApiTelegramException(method_name, result, result_json)
telebot.apihelper.ApiTelegramException: A request to the Telegram API was unsuccessful. Error code: 409. Description: Conflict: terminated by other getUpdates request; make sure that only one bot instance is running

ERROR:TeleBot:Threaded polling exception: A request to the Telegram API was unsuccessful. Error code: 409. Description: Conflict: terminated by other getUpdates request; make sure that only one bot instance is running
ERROR:TeleBot:Exception traceback:
Traceback (most recent call last):
  File "C:\Users\Asus\AppData\Local\Programs\Python\Python310\lib\site-packages\telebot\__init__.py", line 1077, in __threaded_polling
    polling_thread.raise_exceptions()
  File "C:\Users\Asus\AppData\Local\Programs\Python\Python310\lib\site-packages\telebot\util.py", line 116, in raise_exceptions
    raise self.exception_info
  File "C:\Users\Asus\AppData\Local\Programs\Python\Python310\lib\site-packages\telebot\util.py", line 98, in run
    task(*args, **kwargs)
  File "C:\Users\Asus\AppData\Local\Programs\Python\Python310\lib\site-packages\telebot\__init__.py", line 653, in __retrieve_updates
    updates = self.get_updates(offset=(self.last_update_id + 1),
  File "C:\Users\Asus\AppData\Local\Programs\Python\Python310\lib\site-packages\telebot\__init__.py", line 627, in get_updates
    json_updates = apihelper.get_updates(self.token, offset, limit, timeout, allowed_updates, long_polling_timeout)
  File "C:\Users\Asus\AppData\Local\Programs\Python\Python310\lib\site-packages\telebot\apihelper.py", line 334, in get_updates
    return _make_request(token, method_url, params=payload)
  File "C:\Users\Asus\AppData\Local\Programs\Python\Python310\lib\site-packages\telebot\apihelper.py", line 162, in _make_request
    json_result = _check_result(method_name, result)
  File "C:\Users\Asus\AppData\Local\Programs\Python\Python310\lib\site-packages\telebot\apihelper.py", line 189, in _check_result
    raise ApiTelegramException(method_name, result, result_json)
telebot.apihelper.ApiTelegramException: A request to the Telegram API was unsuccessful. Error code: 409. Description: Conflict: terminated by other getUpdates request; make sure that only one bot instance is running

ERROR:TeleBot:Threaded polling exception: A request to the Telegram API was unsuccessful. Error code: 409. Description: Conflict: terminated by other getUpdates request; make sure that only one bot instance is running
ERROR:TeleBot:Exception traceback:
Traceback (most recent call last):
  File "C:\Users\Asus\AppData\Local\Programs\Python\Python310\lib\site-packages\telebot\__init__.py", line 1077, in __threaded_polling
    polling_thread.raise_exceptions()
  File "C:\Users\Asus\AppData\Local\Programs\Python\Python310\lib\site-packages\telebot\util.py", line 116, in raise_exceptions
    raise self.exception_info
  File "C:\Users\Asus\AppData\Local\Programs\Python\Python310\lib\site-packages\telebot\util.py", line 98, in run
    task(*args, **kwargs)
  File "C:\Users\Asus\AppData\Local\Programs\Python\Python310\lib\site-packages\telebot\__init__.py", line 653, in __retrieve_updates
    updates = self.get_updates(offset=(self.last_update_id + 1),
  File "C:\Users\Asus\AppData\Local\Programs\Python\Python310\lib\site-packages\telebot\__init__.py", line 627, in get_updates
    json_updates = apihelper.get_updates(self.token, offset, limit, timeout, allowed_updates, long_polling_timeout)
  File "C:\Users\Asus\AppData\Local\Programs\Python\Python310\lib\site-packages\telebot\apihelper.py", line 334, in get_updates
    return _make_request(token, method_url, params=payload)
  File "C:\Users\Asus\AppData\Local\Programs\Python\Python310\lib\site-packages\telebot\apihelper.py", line 162, in _make_request
    json_result = _check_result(method_name, result)
  File "C:\Users\Asus\AppData\Local\Programs\Python\Python310\lib\site-packages\telebot\apihelper.py", line 189, in _check_result
    raise ApiTelegramException(method_name, result, result_json)
telebot.apihelper.ApiTelegramException: A request to the Telegram API was unsuccessful. Error code: 409. Description: Conflict: terminated by other getUpdates request; make sure that only one bot instance is running

ERROR:TeleBot:Threaded polling exception: A request to the Telegram API was unsuccessful. Error code: 409. Description: Conflict: terminated by other getUpdates request; make sure that only one bot instance is running
ERROR:TeleBot:Exception traceback:
Traceback (most recent call last):
  File "C:\Users\Asus\AppData\Local\Programs\Python\Python310\lib\site-packages\telebot\__init__.py", line 1077, in __threaded_polling
    polling_thread.raise_exceptions()
  File "C:\Users\Asus\AppData\Local\Programs\Python\Python310\lib\site-packages\telebot\util.py", line 116, in raise_exceptions
    raise self.exception_info
  File "C:\Users\Asus\AppData\Local\Programs\Python\Python310\lib\site-packages\telebot\util.py", line 98, in run
    task(*args, **kwargs)
  File "C:\Users\Asus\AppData\Local\Programs\Python\Python310\lib\site-packages\telebot\__init__.py", line 653, in __retrieve_updates
    updates = self.get_updates(offset=(self.last_update_id + 1),
  File "C:\Users\Asus\AppData\Local\Programs\Python\Python310\lib\site-packages\telebot\__init__.py", line 627, in get_updates
    json_updates = apihelper.get_updates(self.token, offset, limit, timeout, allowed_updates, long_polling_timeout)
  File "C:\Users\Asus\AppData\Local\Programs\Python\Python310\lib\site-packages\telebot\apihelper.py", line 334, in get_updates
    return _make_request(token, method_url, params=payload)
  File "C:\Users\Asus\AppData\Local\Programs\Python\Python310\lib\site-packages\telebot\apihelper.py", line 162, in _make_request
    json_result = _check_result(method_name, result)
  File "C:\Users\Asus\AppData\Local\Programs\Python\Python310\lib\site-packages\telebot\apihelper.py", line 189, in _check_result
    raise ApiTelegramException(method_name, result, result_json)
telebot.apihelper.ApiTelegramException: A request to the Telegram API was unsuccessful. Error code: 409. Description: Conflict: terminated by other getUpdates request; make sure that only one bot instance is running

ERROR:TeleBot:Threaded polling exception: A request to the Telegram API was unsuccessful. Error code: 409. Description: Conflict: terminated by other getUpdates request; make sure that only one bot instance is running
ERROR:TeleBot:Exception traceback:
Traceback (most recent call last):
  File "C:\Users\Asus\AppData\Local\Programs\Python\Python310\lib\site-packages\telebot\__init__.py", line 1077, in __threaded_polling
    polling_thread.raise_exceptions()
  File "C:\Users\Asus\AppData\Local\Programs\Python\Python310\lib\site-packages\telebot\util.py", line 116, in raise_exceptions
    raise self.exception_info
  File "C:\Users\Asus\AppData\Local\Programs\Python\Python310\lib\site-packages\telebot\util.py", line 98, in run
    task(*args, **kwargs)
  File "C:\Users\Asus\AppData\Local\Programs\Python\Python310\lib\site-packages\telebot\__init__.py", line 653, in __retrieve_updates
    updates = self.get_updates(offset=(self.last_update_id + 1),
  File "C:\Users\Asus\AppData\Local\Programs\Python\Python310\lib\site-packages\telebot\__init__.py", line 627, in get_updates
    json_updates = apihelper.get_updates(self.token, offset, limit, timeout, allowed_updates, long_polling_timeout)
  File "C:\Users\Asus\AppData\Local\Programs\Python\Python310\lib\site-packages\telebot\apihelper.py", line 334, in get_updates
    return _make_request(token, method_url, params=payload)
  File "C:\Users\Asus\AppData\Local\Programs\Python\Python310\lib\site-packages\telebot\apihelper.py", line 162, in _make_request
    json_result = _check_result(method_name, result)
  File "C:\Users\Asus\AppData\Local\Programs\Python\Python310\lib\site-packages\telebot\apihelper.py", line 189, in _check_result
    raise ApiTelegramException(method_name, result, result_json)
telebot.apihelper.ApiTelegramException: A request to the Telegram API was unsuccessful. Error code: 409. Description: Conflict: terminated by other getUpdates request; make sure that only one bot instance is running

ERROR:TeleBot:Threaded polling exception: A request to the Telegram API was unsuccessful. Error code: 409. Description: Conflict: terminated by other getUpdates request; make sure that only one bot instance is running
ERROR:TeleBot:Exception traceback:
Traceback (most recent call last):
  File "C:\Users\Asus\AppData\Local\Programs\Python\Python310\lib\site-packages\telebot\__init__.py", line 1077, in __threaded_polling
    polling_thread.raise_exceptions()
  File "C:\Users\Asus\AppData\Local\Programs\Python\Python310\lib\site-packages\telebot\util.py", line 116, in raise_exceptions
    raise self.exception_info
  File "C:\Users\Asus\AppData\Local\Programs\Python\Python310\lib\site-packages\telebot\util.py", line 98, in run
    task(*args, **kwargs)
  File "C:\Users\Asus\AppData\Local\Programs\Python\Python310\lib\site-packages\telebot\__init__.py", line 653, in __retrieve_updates
    updates = self.get_updates(offset=(self.last_update_id + 1),
  File "C:\Users\Asus\AppData\Local\Programs\Python\Python310\lib\site-packages\telebot\__init__.py", line 627, in get_updates
    json_updates = apihelper.get_updates(self.token, offset, limit, timeout, allowed_updates, long_polling_timeout)
  File "C:\Users\Asus\AppData\Local\Programs\Python\Python310\lib\site-packages\telebot\apihelper.py", line 334, in get_updates
    return _make_request(token, method_url, params=payload)
  File "C:\Users\Asus\AppData\Local\Programs\Python\Python310\lib\site-packages\telebot\apihelper.py", line 162, in _make_request
    json_result = _check_result(method_name, result)
  File "C:\Users\Asus\AppData\Local\Programs\Python\Python310\lib\site-packages\telebot\apihelper.py", line 189, in _check_result
    raise ApiTelegramException(method_name, result, result_json)
telebot.apihelper.ApiTelegramException: A request to the Telegram API was unsuccessful. Error code: 409. Description: Conflict: terminated by other getUpdates request; make sure that only one bot instance is running

ERROR:TeleBot:Threaded polling exception: A request to the Telegram API was unsuccessful. Error code: 409. Description: Conflict: terminated by other getUpdates request; make sure that only one bot instance is running
ERROR:TeleBot:Exception traceback:
Traceback (most recent call last):
  File "C:\Users\Asus\AppData\Local\Programs\Python\Python310\lib\site-packages\telebot\__init__.py", line 1077, in __threaded_polling
    polling_thread.raise_exceptions()
  File "C:\Users\Asus\AppData\Local\Programs\Python\Python310\lib\site-packages\telebot\util.py", line 116, in raise_exceptions
    raise self.exception_info
  File "C:\Users\Asus\AppData\Local\Programs\Python\Python310\lib\site-packages\telebot\util.py", line 98, in run
    task(*args, **kwargs)
  File "C:\Users\Asus\AppData\Local\Programs\Python\Python310\lib\site-packages\telebot\__init__.py", line 653, in __retrieve_updates
    updates = self.get_updates(offset=(self.last_update_id + 1),
  File "C:\Users\Asus\AppData\Local\Programs\Python\Python310\lib\site-packages\telebot\__init__.py", line 627, in get_updates
    json_updates = apihelper.get_updates(self.token, offset, limit, timeout, allowed_updates, long_polling_timeout)
  File "C:\Users\Asus\AppData\Local\Programs\Python\Python310\lib\site-packages\telebot\apihelper.py", line 334, in get_updates
    return _make_request(token, method_url, params=payload)
  File "C:\Users\Asus\AppData\Local\Programs\Python\Python310\lib\site-packages\telebot\apihelper.py", line 162, in _make_request
    json_result = _check_result(method_name, result)
  File "C:\Users\Asus\AppData\Local\Programs\Python\Python310\lib\site-packages\telebot\apihelper.py", line 189, in _check_result
    raise ApiTelegramException(method_name, result, result_json)
telebot.apihelper.ApiTelegramException: A request to the Telegram API was unsuccessful. Error code: 409. Description: Conflict: terminated by other getUpdates request; make sure that only one bot instance is running

ERROR:TeleBot:Threaded polling exception: A request to the Telegram API was unsuccessful. Error code: 409. Description: Conflict: terminated by other getUpdates request; make sure that only one bot instance is running
ERROR:TeleBot:Exception traceback:
Traceback (most recent call last):
  File "C:\Users\Asus\AppData\Local\Programs\Python\Python310\lib\site-packages\telebot\__init__.py", line 1077, in __threaded_polling
    polling_thread.raise_exceptions()
  File "C:\Users\Asus\AppData\Local\Programs\Python\Python310\lib\site-packages\telebot\util.py", line 116, in raise_exceptions
    raise self.exception_info
  File "C:\Users\Asus\AppData\Local\Programs\Python\Python310\lib\site-packages\telebot\util.py", line 98, in run
    task(*args, **kwargs)
  File "C:\Users\Asus\AppData\Local\Programs\Python\Python310\lib\site-packages\telebot\__init__.py", line 653, in __retrieve_updates
    updates = self.get_updates(offset=(self.last_update_id + 1),
  File "C:\Users\Asus\AppData\Local\Programs\Python\Python310\lib\site-packages\telebot\__init__.py", line 627, in get_updates
    json_updates = apihelper.get_updates(self.token, offset, limit, timeout, allowed_updates, long_polling_timeout)
  File "C:\Users\Asus\AppData\Local\Programs\Python\Python310\lib\site-packages\telebot\apihelper.py", line 334, in get_updates
    return _make_request(token, method_url, params=payload)
  File "C:\Users\Asus\AppData\Local\Programs\Python\Python310\lib\site-packages\telebot\apihelper.py", line 162, in _make_request
    json_result = _check_result(method_name, result)
  File "C:\Users\Asus\AppData\Local\Programs\Python\Python310\lib\site-packages\telebot\apihelper.py", line 189, in _check_result
    raise ApiTelegramException(method_name, result, result_json)
telebot.apihelper.ApiTelegramException: A request to the Telegram API was unsuccessful. Error code: 409. Description: Conflict: terminated by other getUpdates request; make sure that only one bot instance is running

ERROR:TeleBot:Threaded polling exception: A request to the Telegram API was unsuccessful. Error code: 409. Description: Conflict: terminated by other getUpdates request; make sure that only one bot instance is running
ERROR:TeleBot:Exception traceback:
Traceback (most recent call last):
  File "C:\Users\Asus\AppData\Local\Programs\Python\Python310\lib\site-packages\telebot\__init__.py", line 1077, in __threaded_polling
    polling_thread.raise_exceptions()
  File "C:\Users\Asus\AppData\Local\Programs\Python\Python310\lib\site-packages\telebot\util.py", line 116, in raise_exceptions
    raise self.exception_info
  File "C:\Users\Asus\AppData\Local\Programs\Python\Python310\lib\site-packages\telebot\util.py", line 98, in run
    task(*args, **kwargs)
  File "C:\Users\Asus\AppData\Local\Programs\Python\Python310\lib\site-packages\telebot\__init__.py", line 653, in __retrieve_updates
    updates = self.get_updates(offset=(self.last_update_id + 1),
  File "C:\Users\Asus\AppData\Local\Programs\Python\Python310\lib\site-packages\telebot\__init__.py", line 627, in get_updates
    json_updates = apihelper.get_updates(self.token, offset, limit, timeout, allowed_updates, long_polling_timeout)
  File "C:\Users\Asus\AppData\Local\Programs\Python\Python310\lib\site-packages\telebot\apihelper.py", line 334, in get_updates
    return _make_request(token, method_url, params=payload)
  File "C:\Users\Asus\AppData\Local\Programs\Python\Python310\lib\site-packages\telebot\apihelper.py", line 162, in _make_request
    json_result = _check_result(method_name, result)
  File "C:\Users\Asus\AppData\Local\Programs\Python\Python310\lib\site-packages\telebot\apihelper.py", line 189, in _check_result
    raise ApiTelegramException(method_name, result, result_json)
telebot.apihelper.ApiTelegramException: A request to the Telegram API was unsuccessful. Error code: 409. Description: Conflict: terminated by other getUpdates request; make sure that only one bot instance is running

ERROR:TeleBot:Threaded polling exception: A request to the Telegram API was unsuccessful. Error code: 409. Description: Conflict: terminated by other getUpdates request; make sure that only one bot instance is running
ERROR:TeleBot:Exception traceback:
Traceback (most recent call last):
  File "C:\Users\Asus\AppData\Local\Programs\Python\Python310\lib\site-packages\telebot\__init__.py", line 1077, in __threaded_polling
    polling_thread.raise_exceptions()
  File "C:\Users\Asus\AppData\Local\Programs\Python\Python310\lib\site-packages\telebot\util.py", line 116, in raise_exceptions
    raise self.exception_info
  File "C:\Users\Asus\AppData\Local\Programs\Python\Python310\lib\site-packages\telebot\util.py", line 98, in run
    task(*args, **kwargs)
  File "C:\Users\Asus\AppData\Local\Programs\Python\Python310\lib\site-packages\telebot\__init__.py", line 653, in __retrieve_updates
    updates = self.get_updates(offset=(self.last_update_id + 1),
  File "C:\Users\Asus\AppData\Local\Programs\Python\Python310\lib\site-packages\telebot\__init__.py", line 627, in get_updates
    json_updates = apihelper.get_updates(self.token, offset, limit, timeout, allowed_updates, long_polling_timeout)
  File "C:\Users\Asus\AppData\Local\Programs\Python\Python310\lib\site-packages\telebot\apihelper.py", line 334, in get_updates
    return _make_request(token, method_url, params=payload)
  File "C:\Users\Asus\AppData\Local\Programs\Python\Python310\lib\site-packages\telebot\apihelper.py", line 162, in _make_request
    json_result = _check_result(method_name, result)
  File "C:\Users\Asus\AppData\Local\Programs\Python\Python310\lib\site-packages\telebot\apihelper.py", line 189, in _check_result
    raise ApiTelegramException(method_name, result, result_json)
telebot.apihelper.ApiTelegramException: A request to the Telegram API was unsuccessful. Error code: 409. Description: Conflict: terminated by other getUpdates request; make sure that only one bot instance is running

ERROR:TeleBot:Threaded polling exception: A request to the Telegram API was unsuccessful. Error code: 409. Description: Conflict: terminated by other getUpdates request; make sure that only one bot instance is running
ERROR:TeleBot:Exception traceback:
Traceback (most recent call last):
  File "C:\Users\Asus\AppData\Local\Programs\Python\Python310\lib\site-packages\telebot\__init__.py", line 1077, in __threaded_polling
    polling_thread.raise_exceptions()
  File "C:\Users\Asus\AppData\Local\Programs\Python\Python310\lib\site-packages\telebot\util.py", line 116, in raise_exceptions
    raise self.exception_info
  File "C:\Users\Asus\AppData\Local\Programs\Python\Python310\lib\site-packages\telebot\util.py", line 98, in run
    task(*args, **kwargs)
  File "C:\Users\Asus\AppData\Local\Programs\Python\Python310\lib\site-packages\telebot\__init__.py", line 653, in __retrieve_updates
    updates = self.get_updates(offset=(self.last_update_id + 1),
  File "C:\Users\Asus\AppData\Local\Programs\Python\Python310\lib\site-packages\telebot\__init__.py", line 627, in get_updates
    json_updates = apihelper.get_updates(self.token, offset, limit, timeout, allowed_updates, long_polling_timeout)
  File "C:\Users\Asus\AppData\Local\Programs\Python\Python310\lib\site-packages\telebot\apihelper.py", line 334, in get_updates
    return _make_request(token, method_url, params=payload)
  File "C:\Users\Asus\AppData\Local\Programs\Python\Python310\lib\site-packages\telebot\apihelper.py", line 162, in _make_request
    json_result = _check_result(method_name, result)
  File "C:\Users\Asus\AppData\Local\Programs\Python\Python310\lib\site-packages\telebot\apihelper.py", line 189, in _check_result
    raise ApiTelegramException(method_name, result, result_json)
telebot.apihelper.ApiTelegramException: A request to the Telegram API was unsuccessful. Error code: 409. Description: Conflict: terminated by other getUpdates request; make sure that only one bot instance is running

ERROR:TeleBot:Threaded polling exception: A request to the Telegram API was unsuccessful. Error code: 409. Description: Conflict: terminated by other getUpdates request; make sure that only one bot instance is running
ERROR:TeleBot:Exception traceback:
Traceback (most recent call last):
  File "C:\Users\Asus\AppData\Local\Programs\Python\Python310\lib\site-packages\telebot\__init__.py", line 1077, in __threaded_polling
    polling_thread.raise_exceptions()
  File "C:\Users\Asus\AppData\Local\Programs\Python\Python310\lib\site-packages\telebot\util.py", line 116, in raise_exceptions
    raise self.exception_info
  File "C:\Users\Asus\AppData\Local\Programs\Python\Python310\lib\site-packages\telebot\util.py", line 98, in run
    task(*args, **kwargs)
  File "C:\Users\Asus\AppData\Local\Programs\Python\Python310\lib\site-packages\telebot\__init__.py", line 653, in __retrieve_updates
    updates = self.get_updates(offset=(self.last_update_id + 1),
  File "C:\Users\Asus\AppData\Local\Programs\Python\Python310\lib\site-packages\telebot\__init__.py", line 627, in get_updates
    json_updates = apihelper.get_updates(self.token, offset, limit, timeout, allowed_updates, long_polling_timeout)
  File "C:\Users\Asus\AppData\Local\Programs\Python\Python310\lib\site-packages\telebot\apihelper.py", line 334, in get_updates
    return _make_request(token, method_url, params=payload)
  File "C:\Users\Asus\AppData\Local\Programs\Python\Python310\lib\site-packages\telebot\apihelper.py", line 162, in _make_request
    json_result = _check_result(method_name, result)
  File "C:\Users\Asus\AppData\Local\Programs\Python\Python310\lib\site-packages\telebot\apihelper.py", line 189, in _check_result
    raise ApiTelegramException(method_name, result, result_json)
telebot.apihelper.ApiTelegramException: A request to the Telegram API was unsuccessful. Error code: 409. Description: Conflict: terminated by other getUpdates request; make sure that only one bot instance is running

ERROR:TeleBot:Threaded polling exception: A request to the Telegram API was unsuccessful. Error code: 409. Description: Conflict: terminated by other getUpdates request; make sure that only one bot instance is running
ERROR:TeleBot:Exception traceback:
Traceback (most recent call last):
  File "C:\Users\Asus\AppData\Local\Programs\Python\Python310\lib\site-packages\telebot\__init__.py", line 1077, in __threaded_polling
    polling_thread.raise_exceptions()
  File "C:\Users\Asus\AppData\Local\Programs\Python\Python310\lib\site-packages\telebot\util.py", line 116, in raise_exceptions
    raise self.exception_info
  File "C:\Users\Asus\AppData\Local\Programs\Python\Python310\lib\site-packages\telebot\util.py", line 98, in run
    task(*args, **kwargs)
  File "C:\Users\Asus\AppData\Local\Programs\Python\Python310\lib\site-packages\telebot\__init__.py", line 653, in __retrieve_updates
    updates = self.get_updates(offset=(self.last_update_id + 1),
  File "C:\Users\Asus\AppData\Local\Programs\Python\Python310\lib\site-packages\telebot\__init__.py", line 627, in get_updates
    json_updates = apihelper.get_updates(self.token, offset, limit, timeout, allowed_updates, long_polling_timeout)
  File "C:\Users\Asus\AppData\Local\Programs\Python\Python310\lib\site-packages\telebot\apihelper.py", line 334, in get_updates
    return _make_request(token, method_url, params=payload)
  File "C:\Users\Asus\AppData\Local\Programs\Python\Python310\lib\site-packages\telebot\apihelper.py", line 162, in _make_request
    json_result = _check_result(method_name, result)
  File "C:\Users\Asus\AppData\Local\Programs\Python\Python310\lib\site-packages\telebot\apihelper.py", line 189, in _check_result
    raise ApiTelegramException(method_name, result, result_json)
telebot.apihelper.ApiTelegramException: A request to the Telegram API was unsuccessful. Error code: 409. Description: Conflict: terminated by other getUpdates request; make sure that only one bot instance is running

ERROR:TeleBot:Threaded polling exception: A request to the Telegram API was unsuccessful. Error code: 409. Description: Conflict: terminated by other getUpdates request; make sure that only one bot instance is running
ERROR:TeleBot:Exception traceback:
Traceback (most recent call last):
  File "C:\Users\Asus\AppData\Local\Programs\Python\Python310\lib\site-packages\telebot\__init__.py", line 1077, in __threaded_polling
    polling_thread.raise_exceptions()
  File "C:\Users\Asus\AppData\Local\Programs\Python\Python310\lib\site-packages\telebot\util.py", line 116, in raise_exceptions
    raise self.exception_info
  File "C:\Users\Asus\AppData\Local\Programs\Python\Python310\lib\site-packages\telebot\util.py", line 98, in run
    task(*args, **kwargs)
  File "C:\Users\Asus\AppData\Local\Programs\Python\Python310\lib\site-packages\telebot\__init__.py", line 653, in __retrieve_updates
    updates = self.get_updates(offset=(self.last_update_id + 1),
  File "C:\Users\Asus\AppData\Local\Programs\Python\Python310\lib\site-packages\telebot\__init__.py", line 627, in get_updates
    json_updates = apihelper.get_updates(self.token, offset, limit, timeout, allowed_updates, long_polling_timeout)
  File "C:\Users\Asus\AppData\Local\Programs\Python\Python310\lib\site-packages\telebot\apihelper.py", line 334, in get_updates
    return _make_request(token, method_url, params=payload)
  File "C:\Users\Asus\AppData\Local\Programs\Python\Python310\lib\site-packages\telebot\apihelper.py", line 162, in _make_request
    json_result = _check_result(method_name, result)
  File "C:\Users\Asus\AppData\Local\Programs\Python\Python310\lib\site-packages\telebot\apihelper.py", line 189, in _check_result
    raise ApiTelegramException(method_name, result, result_json)
telebot.apihelper.ApiTelegramException: A request to the Telegram API was unsuccessful. Error code: 409. Description: Conflict: terminated by other getUpdates request; make sure that only one bot instance is running

ERROR:TeleBot:Threaded polling exception: A request to the Telegram API was unsuccessful. Error code: 409. Description: Conflict: terminated by other getUpdates request; make sure that only one bot instance is running
ERROR:TeleBot:Exception traceback:
Traceback (most recent call last):
  File "C:\Users\Asus\AppData\Local\Programs\Python\Python310\lib\site-packages\telebot\__init__.py", line 1077, in __threaded_polling
    polling_thread.raise_exceptions()
  File "C:\Users\Asus\AppData\Local\Programs\Python\Python310\lib\site-packages\telebot\util.py", line 116, in raise_exceptions
    raise self.exception_info
  File "C:\Users\Asus\AppData\Local\Programs\Python\Python310\lib\site-packages\telebot\util.py", line 98, in run
    task(*args, **kwargs)
  File "C:\Users\Asus\AppData\Local\Programs\Python\Python310\lib\site-packages\telebot\__init__.py", line 653, in __retrieve_updates
    updates = self.get_updates(offset=(self.last_update_id + 1),
  File "C:\Users\Asus\AppData\Local\Programs\Python\Python310\lib\site-packages\telebot\__init__.py", line 627, in get_updates
    json_updates = apihelper.get_updates(self.token, offset, limit, timeout, allowed_updates, long_polling_timeout)
  File "C:\Users\Asus\AppData\Local\Programs\Python\Python310\lib\site-packages\telebot\apihelper.py", line 334, in get_updates
    return _make_request(token, method_url, params=payload)
  File "C:\Users\Asus\AppData\Local\Programs\Python\Python310\lib\site-packages\telebot\apihelper.py", line 162, in _make_request
    json_result = _check_result(method_name, result)
  File "C:\Users\Asus\AppData\Local\Programs\Python\Python310\lib\site-packages\telebot\apihelper.py", line 189, in _check_result
    raise ApiTelegramException(method_name, result, result_json)
telebot.apihelper.ApiTelegramException: A request to the Telegram API was unsuccessful. Error code: 409. Description: Conflict: terminated by other getUpdates request; make sure that only one bot instance is running

ERROR:TeleBot:Threaded polling exception: A request to the Telegram API was unsuccessful. Error code: 409. Description: Conflict: terminated by other getUpdates request; make sure that only one bot instance is running
ERROR:TeleBot:Exception traceback:
Traceback (most recent call last):
  File "C:\Users\Asus\AppData\Local\Programs\Python\Python310\lib\site-packages\telebot\__init__.py", line 1077, in __threaded_polling
    polling_thread.raise_exceptions()
  File "C:\Users\Asus\AppData\Local\Programs\Python\Python310\lib\site-packages\telebot\util.py", line 116, in raise_exceptions
    raise self.exception_info
  File "C:\Users\Asus\AppData\Local\Programs\Python\Python310\lib\site-packages\telebot\util.py", line 98, in run
    task(*args, **kwargs)
  File "C:\Users\Asus\AppData\Local\Programs\Python\Python310\lib\site-packages\telebot\__init__.py", line 653, in __retrieve_updates
    updates = self.get_updates(offset=(self.last_update_id + 1),
  File "C:\Users\Asus\AppData\Local\Programs\Python\Python310\lib\site-packages\telebot\__init__.py", line 627, in get_updates
    json_updates = apihelper.get_updates(self.token, offset, limit, timeout, allowed_updates, long_polling_timeout)
  File "C:\Users\Asus\AppData\Local\Programs\Python\Python310\lib\site-packages\telebot\apihelper.py", line 334, in get_updates
    return _make_request(token, method_url, params=payload)
  File "C:\Users\Asus\AppData\Local\Programs\Python\Python310\lib\site-packages\telebot\apihelper.py", line 162, in _make_request
    json_result = _check_result(method_name, result)
  File "C:\Users\Asus\AppData\Local\Programs\Python\Python310\lib\site-packages\telebot\apihelper.py", line 189, in _check_result
    raise ApiTelegramException(method_name, result, result_json)
telebot.apihelper.ApiTelegramException: A request to the Telegram API was unsuccessful. Error code: 409. Description: Conflict: terminated by other getUpdates request; make sure that only one bot instance is running

ERROR:TeleBot:Threaded polling exception: A request to the Telegram API was unsuccessful. Error code: 409. Description: Conflict: terminated by other getUpdates request; make sure that only one bot instance is running
ERROR:TeleBot:Exception traceback:
Traceback (most recent call last):
  File "C:\Users\Asus\AppData\Local\Programs\Python\Python310\lib\site-packages\telebot\__init__.py", line 1077, in __threaded_polling
    polling_thread.raise_exceptions()
  File "C:\Users\Asus\AppData\Local\Programs\Python\Python310\lib\site-packages\telebot\util.py", line 116, in raise_exceptions
    raise self.exception_info
  File "C:\Users\Asus\AppData\Local\Programs\Python\Python310\lib\site-packages\telebot\util.py", line 98, in run
    task(*args, **kwargs)
  File "C:\Users\Asus\AppData\Local\Programs\Python\Python310\lib\site-packages\telebot\__init__.py", line 653, in __retrieve_updates
    updates = self.get_updates(offset=(self.last_update_id + 1),
  File "C:\Users\Asus\AppData\Local\Programs\Python\Python310\lib\site-packages\telebot\__init__.py", line 627, in get_updates
    json_updates = apihelper.get_updates(self.token, offset, limit, timeout, allowed_updates, long_polling_timeout)
  File "C:\Users\Asus\AppData\Local\Programs\Python\Python310\lib\site-packages\telebot\apihelper.py", line 334, in get_updates
    return _make_request(token, method_url, params=payload)
  File "C:\Users\Asus\AppData\Local\Programs\Python\Python310\lib\site-packages\telebot\apihelper.py", line 162, in _make_request
    json_result = _check_result(method_name, result)
  File "C:\Users\Asus\AppData\Local\Programs\Python\Python310\lib\site-packages\telebot\apihelper.py", line 189, in _check_result
    raise ApiTelegramException(method_name, result, result_json)
telebot.apihelper.ApiTelegramException: A request to the Telegram API was unsuccessful. Error code: 409. Description: Conflict: terminated by other getUpdates request; make sure that only one bot instance is running

ERROR:TeleBot:Threaded polling exception: A request to the Telegram API was unsuccessful. Error code: 409. Description: Conflict: terminated by other getUpdates request; make sure that only one bot instance is running
ERROR:TeleBot:Exception traceback:
Traceback (most recent call last):
  File "C:\Users\Asus\AppData\Local\Programs\Python\Python310\lib\site-packages\telebot\__init__.py", line 1077, in __threaded_polling
    polling_thread.raise_exceptions()
  File "C:\Users\Asus\AppData\Local\Programs\Python\Python310\lib\site-packages\telebot\util.py", line 116, in raise_exceptions
    raise self.exception_info
  File "C:\Users\Asus\AppData\Local\Programs\Python\Python310\lib\site-packages\telebot\util.py", line 98, in run
    task(*args, **kwargs)
  File "C:\Users\Asus\AppData\Local\Programs\Python\Python310\lib\site-packages\telebot\__init__.py", line 653, in __retrieve_updates
    updates = self.get_updates(offset=(self.last_update_id + 1),
  File "C:\Users\Asus\AppData\Local\Programs\Python\Python310\lib\site-packages\telebot\__init__.py", line 627, in get_updates
    json_updates = apihelper.get_updates(self.token, offset, limit, timeout, allowed_updates, long_polling_timeout)
  File "C:\Users\Asus\AppData\Local\Programs\Python\Python310\lib\site-packages\telebot\apihelper.py", line 334, in get_updates
    return _make_request(token, method_url, params=payload)
  File "C:\Users\Asus\AppData\Local\Programs\Python\Python310\lib\site-packages\telebot\apihelper.py", line 162, in _make_request
    json_result = _check_result(method_name, result)
  File "C:\Users\Asus\AppData\Local\Programs\Python\Python310\lib\site-packages\telebot\apihelper.py", line 189, in _check_result
    raise ApiTelegramException(method_name, result, result_json)
telebot.apihelper.ApiTelegramException: A request to the Telegram API was unsuccessful. Error code: 409. Description: Conflict: terminated by other getUpdates request; make sure that only one bot instance is running

ERROR:TeleBot:Threaded polling exception: A request to the Telegram API was unsuccessful. Error code: 409. Description: Conflict: terminated by other getUpdates request; make sure that only one bot instance is running
ERROR:TeleBot:Exception traceback:
Traceback (most recent call last):
  File "C:\Users\Asus\AppData\Local\Programs\Python\Python310\lib\site-packages\telebot\__init__.py", line 1077, in __threaded_polling
    polling_thread.raise_exceptions()
  File "C:\Users\Asus\AppData\Local\Programs\Python\Python310\lib\site-packages\telebot\util.py", line 116, in raise_exceptions
    raise self.exception_info
  File "C:\Users\Asus\AppData\Local\Programs\Python\Python310\lib\site-packages\telebot\util.py", line 98, in run
    task(*args, **kwargs)
  File "C:\Users\Asus\AppData\Local\Programs\Python\Python310\lib\site-packages\telebot\__init__.py", line 653, in __retrieve_updates
    updates = self.get_updates(offset=(self.last_update_id + 1),
  File "C:\Users\Asus\AppData\Local\Programs\Python\Python310\lib\site-packages\telebot\__init__.py", line 627, in get_updates
    json_updates = apihelper.get_updates(self.token, offset, limit, timeout, allowed_updates, long_polling_timeout)
  File "C:\Users\Asus\AppData\Local\Programs\Python\Python310\lib\site-packages\telebot\apihelper.py", line 334, in get_updates
    return _make_request(token, method_url, params=payload)
  File "C:\Users\Asus\AppData\Local\Programs\Python\Python310\lib\site-packages\telebot\apihelper.py", line 162, in _make_request
    json_result = _check_result(method_name, result)
  File "C:\Users\Asus\AppData\Local\Programs\Python\Python310\lib\site-packages\telebot\apihelper.py", line 189, in _check_result
    raise ApiTelegramException(method_name, result, result_json)
telebot.apihelper.ApiTelegramException: A request to the Telegram API was unsuccessful. Error code: 409. Description: Conflict: terminated by other getUpdates request; make sure that only one bot instance is running

